Traceback (most recent call last):
  File "./deduper.py", line 66, in <module>
    DUPLICATE_REF_DICT_FORWARD[ref_key].append(umi)
KeyError: ('2', 164305591)
Command exited with non-zero status 1
	Command being timed: "./deduper.py -file /home/svillarr/shared/deduper/Dataset2.sam"
	User time (seconds): 3.96
	System time (seconds): 0.13
	Percent of CPU this job got: 98%
	Elapsed (wall clock) time (h:mm:ss or m:ss): 0:04.15
	Average shared text size (kbytes): 0
	Average unshared data size (kbytes): 0
	Average stack size (kbytes): 0
	Average total size (kbytes): 0
	Maximum resident set size (kbytes): 66592
	Average resident set size (kbytes): 0
	Major (requiring I/O) page faults: 0
	Minor (reclaiming a frame) page faults: 43842
	Voluntary context switches: 156
	Involuntary context switches: 9
	Swaps: 0
	File system inputs: 0
	File system outputs: 0
	Socket messages sent: 0
	Socket messages received: 0
	Signals delivered: 0
	Page size (bytes): 4096
	Exit status: 1
